import { Component, ReactNode } from 'react';
import * as Sentry from '@sentry/nextjs';

interface Props {
  children: ReactNode;
  fallback?: ReactNode;
}

interface State {
  hasError: boolean;
  error: Error | null;
}

class ErrorBoundary extends Component<Props, State> {
  public state: State = {
    hasError: false,
    error: null,
  };

  public static getDerivedStateFromError(error: Error): State {
    return { hasError: true, error };
  }

  public componentDidCatch(error: Error, errorInfo: React.ErrorInfo) {
    console.error('Error caught by error boundary:', error, errorInfo);
    
    Sentry.withScope((scope) => {
      scope.setExtras(errorInfo);
      Sentry.captureException(error);
    });
  }

  public render() {
    if (this.state.hasError) {
      if (this.props.fallback) {
        return this.props.fallback;
      }

      return (
        <div className="min-h-screen flex items-center justify-center bg-gray-100">
          <div className="bg-white p-8 rounded-lg shadow-md max-w-md w-full">
            <h2 className="text-2xl font-bold text-red-600 mb-4">
              ¡Ups! Algo salió mal
            </h2>
            <p className="text-gray-600 mb-4">
              Lo sentimos, ha ocurrido un error inesperado. Nuestro equipo ha sido notificado y estamos trabajando en solucionarlo.
            </p>
            <button
              onClick={() => {
                this.setState({ hasError: false, error: null });
                window.location.reload();
              }}
              className="bg-blue-500 hover:bg-blue-600 text-white font-semibold py-2 px-4 rounded transition-colors"
            >
              Recargar página
            </button>
          </div>
        </div>
      );
    }

    return this.props.children;
  }
}

export default ErrorBoundary;
